<?xml version="1.0"?>
<robot xmlns:xacro="http://www.ros.org/wiki/xacro" name="patrolbot">
  <!-- Геометрические параметры вынесены в свойства, чтобы упростить настройку робота под реальное шасси. -->
  <xacro:property name="base_length" value="0.32"/>
  <xacro:property name="base_width" value="0.24"/>
  <xacro:property name="base_height" value="0.10"/>
  <xacro:property name="wheel_radius" value="0.05"/>
  <xacro:property name="wheel_thickness" value="0.03"/>
  <xacro:property name="wheel_offset_y" value="0.12"/>
  <xacro:property name="wheel_offset_x" value="0.0"/>
  <xacro:property name="wheel_offset_z" value="0.05"/>
  <xacro:property name="laser_offset_x" value="0.12"/>
  <xacro:property name="laser_offset_z" value="0.14"/>

  <!-- base_footprint используется как плоская опорная система координат для навигации. -->
  <link name="base_footprint"/>

  <link name="base_link">
    <visual>
      <origin xyz="0 0 ${base_height / 2.0}" rpy="0 0 0"/>
      <geometry>
        <box size="${base_length} ${base_width} ${base_height}"/>
      </geometry>
      <material name="blue">
        <color rgba="0.1 0.3 0.8 1.0"/>
      </material>
    </visual>
    <collision>
      <origin xyz="0 0 ${base_height / 2.0}" rpy="0 0 0"/>
      <geometry>
        <box size="${base_length} ${base_width} ${base_height}"/>
      </geometry>
    </collision>
    <inertial>
      <origin xyz="0 0 ${base_height / 2.0}" rpy="0 0 0"/>
      <mass value="4.5"/>
      <inertia ixx="0.06" ixy="0.0" ixz="0.0" iyy="0.08" iyz="0.0" izz="0.10"/>
    </inertial>
  </link>

  <joint name="base_footprint_to_base_link" type="fixed">
    <parent link="base_footprint"/>
    <child link="base_link"/>
    <origin xyz="0 0 0" rpy="0 0 0"/>
  </joint>

  <link name="left_wheel_link">
    <visual>
      <origin xyz="0 0 0" rpy="1.57079632679 0 0"/>
      <geometry>
        <cylinder radius="${wheel_radius}" length="${wheel_thickness}"/>
      </geometry>
      <material name="black">
        <color rgba="0.1 0.1 0.1 1.0"/>
      </material>
    </visual>
    <collision>
      <origin xyz="0 0 0" rpy="1.57079632679 0 0"/>
      <geometry>
        <cylinder radius="${wheel_radius}" length="${wheel_thickness}"/>
      </geometry>
    </collision>
    <inertial>
      <mass value="0.4"/>
      <inertia ixx="0.001" ixy="0.0" ixz="0.0" iyy="0.001" iyz="0.0" izz="0.001"/>
    </inertial>
  </link>

  <joint name="left_wheel_joint" type="continuous">
    <parent link="base_link"/>
    <child link="left_wheel_link"/>
    <origin xyz="${wheel_offset_x} ${wheel_offset_y} ${wheel_offset_z}" rpy="0 0 0"/>
    <axis xyz="0 1 0"/>
  </joint>

  <link name="right_wheel_link">
    <visual>
      <origin xyz="0 0 0" rpy="1.57079632679 0 0"/>
      <geometry>
        <cylinder radius="${wheel_radius}" length="${wheel_thickness}"/>
      </geometry>
      <material name="black"/>
    </visual>
    <collision>
      <origin xyz="0 0 0" rpy="1.57079632679 0 0"/>
      <geometry>
        <cylinder radius="${wheel_radius}" length="${wheel_thickness}"/>
      </geometry>
    </collision>
    <inertial>
      <mass value="0.4"/>
      <inertia ixx="0.001" ixy="0.0" ixz="0.0" iyy="0.001" iyz="0.0" izz="0.001"/>
    </inertial>
  </link>

  <joint name="right_wheel_joint" type="continuous">
    <parent link="base_link"/>
    <child link="right_wheel_link"/>
    <origin xyz="${wheel_offset_x} -${wheel_offset_y} ${wheel_offset_z}" rpy="0 0 0"/>
    <axis xyz="0 1 0"/>
  </joint>

  <link name="laser_frame">
    <visual>
      <origin xyz="0 0 0" rpy="0 0 0"/>
      <geometry>
        <cylinder radius="0.04" length="0.05"/>
      </geometry>
      <material name="gray">
        <color rgba="0.5 0.5 0.5 1.0"/>
      </material>
    </visual>
    <collision>
      <origin xyz="0 0 0" rpy="0 0 0"/>
      <geometry>
        <cylinder radius="0.04" length="0.05"/>
      </geometry>
    </collision>
    <inertial>
      <mass value="0.2"/>
      <inertia ixx="0.0002" ixy="0.0" ixz="0.0" iyy="0.0002" iyz="0.0" izz="0.0002"/>
    </inertial>
  </link>

  <joint name="laser_joint" type="fixed">
    <parent link="base_link"/>
    <child link="laser_frame"/>
    <origin xyz="${laser_offset_x} 0 ${laser_offset_z}" rpy="0 0 0"/>
  </joint>
</robot>
